<?xml version="1.0" ?>
<robot name="IndyDualArm" xmlns:xacro="http://www.ros.org/wiki/xacro">
  <material name="metal_grey">
    <color rgba="0.5 0.5 0.5 1"/>
  </material>
  <material name="metal_white_grey">
    <color rgba="0.7 0.7 0.7 1"/>
  </material>  
	<link name="world"/>
	<link name="body">
		<inertial>
			<origin rpy="0 0 0" xyz="0 0 0"/>
			<mass value="1.59306955" />
			<inertia ixx="+0.00572623" iyy="+0.00558959" izz="+0.00966674" ixy="+0.00000251" iyz="-0.00000014" ixz="-0.00011380"/>
		</inertial>
		<visual>
			<origin rpy="0 0 0" xyz="0 0 0"/>
			<geometry>
				<mesh filename="meshes/visual/body.stl"/>
			</geometry>
		<material name="metal_grey"/>

		</visual>
		<collision>
			<origin rpy="0 0 0" xyz="0 0 0.11461"/>
			<geometry>
				<box size="0.4 0.6 0.22922" />
			</geometry>
		</collision>
		<collision>
			<origin rpy="0 0 0" xyz="0 0 0.22922"/>
	     <geometry>
	        <sphere radius="0.23"/>
      </geometry>		
		</collision>
	</link>
	
	
 	<joint name="world_fixed" type="fixed">
 		<origin rpy="0 0 0" xyz="0 0 0"/>
 		<parent link="world"/>
		<child link="body"/>
 	</joint>
 
	<link name="neck">	
	    <visual>
	      <origin rpy="0 0 0" xyz="0 0 0"/>
	      <geometry>
		<mesh filename="meshes/visual/neck.stl" scale="1 1 1"/>
	      </geometry>
	      	<material name="metal_grey"/>	        
	    </visual>
	    <inertial>
	      <mass value="0.001"/>
	      <origin rpy="0 0 0" xyz="0.0 0.0 0.0"/>
	      <inertia ixx="0.0" ixy="0.0" ixz="0.0" iyy="0.0" iyz="0.0" izz="0.0"/>
	    </inertial>	
	</link>	
	<link name="neck1">	
	    <visual>
	      <origin rpy="0 0 0" xyz="0 0 0"/>
	      <geometry>
		<mesh filename="meshes/visual/neck1.stl" scale="1 1 1"/>
	      </geometry>
	      	<material name="metal_grey"/>	        
	    </visual>
	    <inertial>
	      <mass value="0.001"/>
	      <origin rpy="0 0 0" xyz="0.0 0.0 0.0"/>
	      <inertia ixx="0.0" ixy="0.0" ixz="0.0" iyy="0.0" iyz="0.0" izz="0.0"/>
	    </inertial>	
	</link>		

	<link name="neck2">	
	    <visual>
	      <origin rpy="1.570796 0 0" xyz="0 0 0"/>
	      <geometry>
						<mesh filename="meshes/visual/neck2.obj" scale="1 1 1"/>
	      </geometry>	        
	    </visual>
	    <inertial>
	      <mass value="2"/>
	      <origin rpy="0 0 0" xyz="0.0 0.0 0.0"/>
	      <inertia ixx="0.0" ixy="0.0" ixz="0.0" iyy="0.0" iyz="0.0" izz="0.0"/>
	    </inertial>	
	</link>		
	<link name="mask">	
	    <visual>
	      <origin rpy="1.570796 0 0" xyz="0 0 0"/>
	      <geometry>
						<mesh filename="meshes/visual/mask.obj" scale="1 1 1"/>
	      </geometry>	        
	    </visual>
	    <inertial>
	      <mass value="2"/>
	      <origin rpy="0 0 0" xyz="0.0 0.0 0.0"/>
	      <inertia ixx="0.0" ixy="0.0" ixz="0.0" iyy="0.0" iyz="0.0" izz="0.0"/>
	    </inertial>	
	</link>		
	<joint name="neck_joint_1" type="fixed">
		<parent link="body"/>
		<child link="neck"/>
		<origin rpy="0.0 0.0 0.0" xyz="0 0 0.489808"/>
	</joint>  		
	<joint name="neck_joint_2" type="revolute">
		<parent link="neck"/>
		<child link="neck1"/>
		<origin rpy="0.0 0.0 0.0" xyz="0 0 0.119694"/>
		<limit effort="10" velocity="1" lower="-3.054325556" upper="3.054325556"/>		
		<axis xyz="0 0 1"/>
	</joint> 
	<joint name="neck_joint_3" type="revolute">
		<parent link="neck1"/>
		<child link="neck2"/>
		<origin rpy="0.0 0.0 0.0" xyz="0.021479 0 0.018994"/>
		<limit effort="10" velocity="1" lower="-3.054325556" upper="3.054325556"/>		
		<axis xyz="0 1 0"/>
	</joint>  
	<joint name="neck_joint_4" type="fixed">
		<parent link="neck2"/>
		<child link="mask"/>
		<origin rpy="0.0 0.0 0.0" xyz="0 0 0"/>
	</joint> 
	<link name="table">	
	    <visual>
	      <origin rpy="0 0 0" xyz="0 0 0"/>
	      <geometry>
						<mesh filename="meshes/visual/table.stl" scale="1 1 1"/>
	      </geometry>	 
	      <material name="metal_white_grey"/>	          
	    </visual>
	    <collision>
	      <origin rpy="0 0 0" xyz="0 0 -0.26024"/>
	      <geometry>
						<box size="1 1.2 0.52048	" />
	      </geometry>	 
	      <material name="metal_white_grey"/>	              
	    </collision>	    
	    <inertial>
	      <mass value="2"/>
	      <origin rpy="0 0 0" xyz="0.0 0.0 0.0"/>
	      <inertia ixx="0.0" ixy="0.0" ixz="0.0" iyy="0.0" iyz="0.0" izz="0.0"/>
	    </inertial>	
	</link>	
	<joint name="table_joint" type="fixed">
		<parent link="body"/>
		<child link="table"/>
		<origin rpy="0.0 0.0 0.0" xyz="0 0 0"/>
	</joint> 
</robot>
