<?xml version="1.0" ?>
<robot name="IndyDualArm" xmlns:xacro="http://www.ros.org/wiki/xacro">
  <material name="metal_grey">
    <color rgba="0.5 0.5 0.5 1"/>
  </material>
  <material name="metal_white_grey">
    <color rgba="0.7 0.7 0.7 1"/>
  </material>  
	<link name="world"/>
	<link name="body">
		<inertial>
			<origin rpy="0 0 0" xyz="0 0 0"/>
			<mass value="1.59306955" />
			<inertia ixx="+0.00572623" iyy="+0.00558959" izz="+0.00966674" ixy="+0.00000251" iyz="-0.00000014" ixz="-0.00011380"/>
		</inertial>
		<visual>
			<origin rpy="0 0 0" xyz="0 0 0"/>
			<geometry>
				<mesh filename="meshes/visual/body.stl"/>
			</geometry>
		<material name="metal_grey"/>

		</visual>
		<collision>
			<origin rpy="0 0 0" xyz="0 0 0.11461"/>
			<geometry>
				<box size="0.4 0.6 0.22922" />
			</geometry>
		</collision>
		<collision>
			<origin rpy="0 0 0" xyz="0 0 0.22922"/>
	     <geometry>
	        <sphere radius="0.23"/>
      </geometry>		
		</collision>
	</link>
	
	<link name="r_0">
		<inertial>
			<origin xyz="0 0 0" rpy="0 0 0"/>
			<mass value="1.59306955"/>
			<inertia ixx="+0.00572623" iyy="+0.00558959" izz="+0.00966674" ixy="+0.00000251" iyz="-0.00000014" ixz="-0.00011380"/>
		</inertial>
		<visual>
			<origin rpy="0 0 0" xyz="0 0 0"/>
			<geometry>
				<mesh filename="meshes/visual/Indy7_0.stl"/>
			</geometry>
	        <material name="metal_grey"/>

		</visual>
		<collision>
			<origin rpy="0 0 0" xyz="0 0 0"/>
			<geometry>
				<mesh filename="meshes/collision/Indy7_0.stl"/>
			</geometry>
		</collision>

	</link>
		<link name="r_1">
		<inertial>
			<origin xyz="0 0 0" rpy="0 0 0"/>
			<mass value="11.8030102"/>
			<inertia ixx="+0.15418559" iyy="+0.12937017" izz="+0.05964415" ixy="-0.00000235" iyz="-0.04854267" ixz="+0.00001739"/>
		</inertial>
		<visual>
			<origin rpy="0 0 0" xyz="0 0 0"/>
			<geometry>
				<mesh filename="meshes/collision/Indy7_1.stl"/>
			</geometry>
		</visual>
		<collision>
			<origin rpy="0 0 0" xyz="0 0 0"/>
			<geometry>
				<mesh filename="meshes/collision/Indy7_1.stl"/>
			</geometry>
		</collision>
	</link>
	<link name="r_2">
		<inertial>
			<origin xyz="0 0 0" rpy="0 0 0"/>
			<mass value="7.99292141"/>
			<inertia ixx="+0.29356980" iyy="+0.28094142" izz="+0.03620609" ixy="-0.00000040" iyz="+0.03727972" ixz="+0.00001441"/>
		</inertial>
		<visual>
			<origin rpy="0 0 0" xyz="0 0 0"/>
			<geometry>
				<mesh filename="meshes/collision/Indy7_2.stl"/>
			</geometry>
		</visual>
		<collision>
			<origin rpy="0 0 0" xyz="0 0 0"/>
			<geometry>
				<mesh filename="meshes/collision/Indy7_2.stl"/>
			</geometry>
		</collision>
	</link>
	<link name="r_3">
		<inertial>
			<origin xyz="0 0 0" rpy="0 0 0"/>
			<mass value="2.99134127"/>
			<inertia ixx="+0.03424593" iyy="+0.03406024" izz="+0.00450477" ixy="+0.00000149" iyz="+0.00186009" ixz="+0.00000724"/>
		</inertial>
		<visual>
			<origin rpy="0 0 0" xyz="0 0 0"/>
			<geometry>
				<mesh filename="meshes/collision/Indy7_3.stl"/>
			</geometry>
		</visual>
		<collision>
			<origin rpy="0 0 0" xyz="0 0 0"/>
			<geometry>
				<mesh filename="meshes/collision/Indy7_3.stl"/>
			</geometry>
		</collision>
	</link>
	<link name="r_4">
		<inertial>
			<origin xyz="0 0 0" rpy="0 0 0"/>
			<mass value="2.12317035"/>
			<inertia ixx="+0.00670405" iyy="+0.00279246" izz="+0.00619341" ixy="+0.00000375" iyz="-0.00127967" ixz="+0.00000150"/>
		</inertial>
		<visual>
			<origin rpy="0 0 0" xyz="0 0 0"/>
			<geometry>
				<mesh filename="meshes/collision/Indy7_4.stl"/>
			</geometry>
		</visual>
		<collision>
			<origin rpy="0 0 0" xyz="0 0 0"/>
			<geometry>
				<mesh filename="meshes/collision/Indy7_4.stl"/>
			</geometry>
		</collision>
	</link>
	<link name="r_5">
		<inertial>
			<origin xyz="0 0 0" rpy="0 0 0"/>
			<mass value="2.28865091"/>
			<inertia ixx="+0.00994891" iyy="+0.00978189" izz="+0.00271492" ixy="+0.00000014" iyz="-0.00093546" ixz="+0.00000321"/>
		</inertial>
		<visual>
			<origin rpy="0 0 0" xyz="0 0 0"/>
			<geometry>
				<mesh filename="meshes/collision/Indy7_5.stl"/>
			</geometry>
		</visual>
		<collision>
			<origin rpy="0 0 0" xyz="0 0 0"/>
			<geometry>
				<mesh filename="meshes/collision/Indy7_5.stl"/>
			</geometry>
		</collision>
	</link>
	<link name="r_6">
		<inertial>
			<origin xyz="0 0 0" rpy="0 0 0"/>
			<mass value="0.40083918"/>
			<inertia ixx="0.00043534" iyy="0.00044549" izz="0.00059634" ixy="+0.00000013" iyz="+0.00000051" ixz="-0.00000002"/>
		</inertial>
		<visual>
			<origin rpy="0 0 0" xyz="0 0 0"/>
			<geometry>
				<mesh filename="meshes/collision/Indy7_6.stl"/>
			</geometry>
		</visual>
		<collision>
			<origin rpy="0 0 0" xyz="0 0 0"/>
			<geometry>
				<mesh filename="meshes/collision/Indy7_6.stl"/>
			</geometry>
		</collision>
	</link>
	<link name="l_0">
		<inertial>
			<origin xyz="0 0 0" rpy="0 0 0"/>
			<mass value="1.59306955"/>
			<inertia ixx="+0.00572623" iyy="+0.00558959" izz="+0.00966674" ixy="+0.00000251" iyz="-0.00000014" ixz="-0.00011380"/>
		</inertial>
		<visual>
			<origin rpy="0 0 0" xyz="0 0 0"/>
			<geometry>
				<mesh filename="meshes/visual/Indy7_0.stl"/>
			</geometry>
	        <material name="metal_grey"/>

		</visual>
		<collision>
			<origin rpy="0 0 0" xyz="0 0 0"/>
			<geometry>
				<mesh filename="meshes/collision/Indy7_0.stl"/>
			</geometry>
		</collision>

	</link>
		<link name="l_1">
		<inertial>
			<origin xyz="0 0 0" rpy="0 0 0"/>
			<mass value="11.8030102"/>
			<inertia ixx="+0.15418559" iyy="+0.12937017" izz="+0.05964415" ixy="-0.00000235" iyz="-0.04854267" ixz="+0.00001739"/>
		</inertial>
		<visual>
			<origin rpy="0 0 0" xyz="0 0 0"/>
			<geometry>
				<mesh filename="meshes/collision/Indy7_1.stl"/>
			</geometry>
		</visual>
		<collision>
			<origin rpy="0 0 0" xyz="0 0 0"/>
			<geometry>
				<mesh filename="meshes/collision/Indy7_1.stl"/>
			</geometry>
		</collision>
	</link>
	<link name="l_2">
		<inertial>
			<origin xyz="0 0 0" rpy="0 0 0"/>
			<mass value="7.99292141"/>
			<inertia ixx="+0.29356980" iyy="+0.28094142" izz="+0.03620609" ixy="-0.00000040" iyz="+0.03727972" ixz="+0.00001441"/>
		</inertial>
		<visual>
			<origin rpy="0 0 0" xyz="0 0 0"/>
			<geometry>
				<mesh filename="meshes/collision/Indy7_2.stl"/>
			</geometry>
		</visual>
		<collision>
			<origin rpy="0 0 0" xyz="0 0 0"/>
			<geometry>
				<mesh filename="meshes/collision/Indy7_2.stl"/>
			</geometry>
		</collision>
	</link>
	<link name="l_3">
		<inertial>
			<origin xyz="0 0 0" rpy="0 0 0"/>
			<mass value="2.99134127"/>
			<inertia ixx="+0.03424593" iyy="+0.03406024" izz="+0.00450477" ixy="+0.00000149" iyz="+0.00186009" ixz="+0.00000724"/>
		</inertial>
		<visual>
			<origin rpy="0 0 0" xyz="0 0 0"/>
			<geometry>
				<mesh filename="meshes/collision/Indy7_3.stl"/>
			</geometry>
		</visual>
		<collision>
			<origin rpy="0 0 0" xyz="0 0 0"/>
			<geometry>
				<mesh filename="meshes/collision/Indy7_3.stl"/>
			</geometry>
		</collision>
	</link>
	<link name="l_4">
		<inertial>
			<origin xyz="0 0 0" rpy="0 0 0"/>
			<mass value="2.12317035"/>
			<inertia ixx="+0.00670405" iyy="+0.00279246" izz="+0.00619341" ixy="+0.00000375" iyz="-0.00127967" ixz="+0.00000150"/>
		</inertial>
		<visual>
			<origin rpy="0 0 0" xyz="0 0 0"/>
			<geometry>
				<mesh filename="meshes/collision/Indy7_4.stl"/>
			</geometry>
		</visual>
		<collision>
			<origin rpy="0 0 0" xyz="0 0 0"/>
			<geometry>
				<mesh filename="meshes/collision/Indy7_4.stl"/>
			</geometry>
		</collision>
	</link>
	<link name="l_5">
		<inertial>
			<origin xyz="0 0 0" rpy="0 0 0"/>
			<mass value="2.28865091"/>
			<inertia ixx="+0.00994891" iyy="+0.00978189" izz="+0.00271492" ixy="+0.00000014" iyz="-0.00093546" ixz="+0.00000321"/>
		</inertial>
		<visual>
			<origin rpy="0 0 0" xyz="0 0 0"/>
			<geometry>
				<mesh filename="meshes/collision/Indy7_5.stl"/>
			</geometry>
		</visual>
		<collision>
			<origin rpy="0 0 0" xyz="0 0 0"/>
			<geometry>
				<mesh filename="meshes/collision/Indy7_5.stl"/>
			</geometry>
		</collision>
	</link>
	<link name="l_6">
		<inertial>
			<origin xyz="0 0 0" rpy="0 0 0"/>
			<mass value="0.40083918"/>
			<inertia ixx="0.00043534" iyy="0.00044549" izz="0.00059634" ixy="+0.00000013" iyz="+0.00000051" ixz="-0.00000002"/>
		</inertial>
		<visual>
			<origin rpy="0 0 0" xyz="0 0 0"/>
			<geometry>
				<mesh filename="meshes/collision/Indy7_6.stl"/>
			</geometry>
		</visual>
		<collision>
			<origin rpy="0 0 0" xyz="0 0 0"/>
			<geometry>
				<mesh filename="meshes/collision/Indy7_6.stl"/>
			</geometry>
		</collision>
	</link>
	<link name="l_tcp">
	    <visual>
	      <origin rpy="1.570796 0 0" xyz="0 0 0"/>
	      <geometry>
		<mesh filename="meshes/visual/axis.obj" scale="0.01 0.01 0.01"/>
	      </geometry>	        
	    </visual>
		
		
	    <inertial>
	      <mass value="2"/>
	      <origin rpy="0 0 0" xyz="0.0 0.0 0.0"/>
	      <inertia ixx="0.0" ixy="0.0" ixz="0.0" iyy="0.0" iyz="0.0" izz="0.0"/>
	    </inertial>	
	</link>
	<link name="r_tcp">	
	    <visual>
	      <origin rpy="1.570796 0 0" xyz="0 0 0"/>
	      <geometry>
		<mesh filename="meshes/visual/axis.obj" scale="0.01 0.01 0.01"/>
	      </geometry>	        
	    </visual>
		
		
	    <inertial>
	      <mass value="2"/>
	      <origin rpy="0 0 0" xyz="0.0 0.0 0.0"/>
	      <inertia ixx="0.0" ixy="0.0" ixz="0.0" iyy="0.0" iyz="0.0" izz="0.0"/>
	    </inertial>	
	</link>	
		
<!-- ---------------------------------------------------------------------------------- -->
 	<joint name="world_fixed" type="fixed">
 		<origin rpy="0 0 0" xyz="0 0 0"/>
 		<parent link="world"/>
		<child link="body"/>
 	</joint>
 	<joint name="r_body_fixed" type="fixed">
 		<origin rpy=" -1.047197333333333 0 0" xyz="0 0.15634 0.37722"/>
		<axis xyz="0 0 1"/>
 		<parent link="body"/>
		<child link="r_0"/>
 	</joint> 	
 	<joint name="l_body_fixed" type="fixed">
 		<origin rpy="-1.047197333333333 0 3.141592" xyz="0 -0.15634 0.37722"/>
		<axis xyz="0 0 1"/>
 		<parent link="body"/>
		<child link="l_0"/>
 	</joint> 	 	
	<joint name="l_joint_0" type="revolute">
 		<origin rpy="0 0 0" xyz="0 0 0.08"/>
		<axis xyz="0 0 1"/>
 		<parent link="l_0"/>
		<child link="l_1"/>
		<limit effort="10" velocity="1" lower="-3.054325556" upper="3.054325556"/>		
 	</joint>
  	<joint name="l_joint_1" type="revolute">
 		<origin rpy="1.5707 1.5707 0" xyz="0 -0.109 0.222"/>
		<axis xyz="0 0 1"/>
 		<parent link="l_1"/>
		<child link="l_2"/>
		<limit effort="10" velocity="1" lower="-3.054325556" upper="3.054325556"/>		
 	</joint>
  	<joint name="l_joint_2" type="revolute">
 		<origin rpy="0 0 0" xyz="-0.45 0 -0.0305"/>
		<axis xyz="0 0 1"/>
 		<parent link="l_2"/>
		<child link="l_3"/>
		<limit effort="10" velocity="1" lower="-3.054325556" upper="3.054325556"/>		
 	</joint>
  	<joint name="l_joint_3" type="revolute">
 		<origin rpy="-1.5707 0 1.5707" xyz="-0.267 0 -0.075"/>
		<axis xyz="0 0 1"/>
 		<parent link="l_3"/>
		<child link="l_4"/>
		<limit effort="10" velocity="1" lower="-3.054325556" upper="3.054325556"/>		

 	</joint>
  	<joint name="l_joint_4" type="revolute">
 		<origin rpy="1.5707 1.5707 0" xyz="0 -0.114 0.083"/>
		<axis xyz="0 0 1"/>
 		<parent link="l_4"/>
		<child link="l_5"/>
		<limit effort="10" velocity="1" lower="-3.054325556" upper="3.054325556"/>		

 	</joint>
  	<joint name="l_joint_5" type="revolute">
 		<origin rpy="-1.5707 0 1.5707" xyz="-0.168 0 0.069"/>
		<axis xyz="0 0 1"/>
 		<parent link="l_5"/>
		<child link="l_6"/>
		<limit effort="10" velocity="1" lower="-3.752457111" upper="3.752457111"/>		

 	</joint>
	<joint name="r_joint_0" type="revolute">
 		<origin rpy="0 0 0" xyz="0 0 0.0775"/>
		<axis xyz="0 0 1"/>
 		<parent link="r_0"/>
		<child link="r_1"/>
		<limit effort="10" velocity="1" lower="-3.054325556" upper="3.054325556"/>		
 	</joint>
  	<joint name="r_joint_1" type="revolute">
 		<origin rpy="1.5707 1.5707 0" xyz="0 -0.109 0.222"/>
		<axis xyz="0 0 1"/>
 		<parent link="r_1"/>
		<child link="r_2"/>
		<limit effort="10" velocity="1" lower="-3.054325556" upper="3.054325556"/>		
 	</joint>
  	<joint name="r_joint_2" type="revolute">
 		<origin rpy="0 0 0" xyz="-0.45 0 -0.0305"/>
		<axis xyz="0 0 1"/>
 		<parent link="r_2"/>
		<child link="r_3"/>
		<limit effort="10" velocity="1" lower="-3.054325556" upper="3.054325556"/>		
 	</joint>
  	<joint name="r_joint_3" type="revolute">
 		<origin rpy="-1.5707 0 1.5707" xyz="-0.267 0 -0.075"/>
		<axis xyz="0 0 1"/>
 		<parent link="r_3"/>
		<child link="r_4"/>
		<limit effort="10" velocity="1" lower="-3.054325556" upper="3.054325556"/>		

 	</joint>
  	<joint name="r_joint_4" type="revolute">
 		<origin rpy="1.5707 1.5707 0" xyz="0 -0.114 0.083"/>
		<axis xyz="0 0 1"/>
 		<parent link="r_4"/>
		<child link="r_5"/>
		<limit effort="10" velocity="1" lower="-3.054325556" upper="3.054325556"/>		

 	</joint>
  	<joint name="r_joint_5" type="revolute">
 		<origin rpy="-1.5707 0 1.5707" xyz="-0.168 0 0.069"/>
		<axis xyz="0 0 1"/>
 		<parent link="r_5"/>
		<child link="r_6"/>
		<limit effort="10" velocity="1" lower="-3.752457111" upper="3.752457111"/>		

 	</joint> 	
	<joint name="l_joint_tcp" type="fixed">
		<parent link="l_6"/>
		<child link="l_tcp"/>
		<origin rpy="0.0 0.0 0.0" xyz="0 0 0.06"/>
	</joint>  	
	<joint name="r_joint_tcp" type="fixed">
		<parent link="r_6"/>
		<child link="r_tcp"/>
		<origin rpy="0.0 0.0 0.0" xyz="0 0 0.06"/>
	</joint>  	
	<link name="neck">	
	    <visual>
	      <origin rpy="0 0 0" xyz="0 0 0"/>
	      <geometry>
		<mesh filename="meshes/visual/neck.stl" scale="1 1 1"/>
	      </geometry>
	      	<material name="metal_grey"/>	        
	    </visual>
	    <inertial>
	      <mass value="0.001"/>
	      <origin rpy="0 0 0" xyz="0.0 0.0 0.0"/>
	      <inertia ixx="0.0" ixy="0.0" ixz="0.0" iyy="0.0" iyz="0.0" izz="0.0"/>
	    </inertial>	
	</link>	
	<link name="neck1">	
	    <visual>
	      <origin rpy="0 0 0" xyz="0 0 0"/>
	      <geometry>
		<mesh filename="meshes/visual/neck1.stl" scale="1 1 1"/>
	      </geometry>
	      	<material name="metal_grey"/>	        
	    </visual>
	    <inertial>
	      <mass value="0.001"/>
	      <origin rpy="0 0 0" xyz="0.0 0.0 0.0"/>
	      <inertia ixx="0.0" ixy="0.0" ixz="0.0" iyy="0.0" iyz="0.0" izz="0.0"/>
	    </inertial>	
	</link>		

	<link name="neck2">	
	    <visual>
	      <origin rpy="1.570796 0 0" xyz="0 0 0"/>
	      <geometry>
						<mesh filename="meshes/visual/neck2.obj" scale="1 1 1"/>
	      </geometry>	        
	    </visual>
	    <inertial>
	      <mass value="2"/>
	      <origin rpy="0 0 0" xyz="0.0 0.0 0.0"/>
	      <inertia ixx="0.0" ixy="0.0" ixz="0.0" iyy="0.0" iyz="0.0" izz="0.0"/>
	    </inertial>	
	</link>		
	<link name="mask">	
	    <visual>
	      <origin rpy="1.570796 0 0" xyz="0 0 0"/>
	      <geometry>
						<mesh filename="meshes/visual/mask.obj" scale="1 1 1"/>
	      </geometry>	        
	    </visual>
	    <inertial>
	      <mass value="2"/>
	      <origin rpy="0 0 0" xyz="0.0 0.0 0.0"/>
	      <inertia ixx="0.0" ixy="0.0" ixz="0.0" iyy="0.0" iyz="0.0" izz="0.0"/>
	    </inertial>	
	</link>		
	<joint name="neck_joint_1" type="fixed">
		<parent link="body"/>
		<child link="neck"/>
		<origin rpy="0.0 0.0 0.0" xyz="0 0 0.489808"/>
	</joint>  		
	<joint name="neck_joint_2" type="revolute">
		<parent link="neck"/>
		<child link="neck1"/>
		<origin rpy="0.0 0.0 0.0" xyz="0 0 0.119694"/>
		<limit effort="10" velocity="1" lower="-3.054325556" upper="3.054325556"/>		
		<axis xyz="0 0 1"/>
	</joint> 
	<joint name="neck_joint_3" type="revolute">
		<parent link="neck1"/>
		<child link="neck2"/>
		<origin rpy="0.0 0.0 0.0" xyz="0.021479 0 0.018994"/>
		<limit effort="10" velocity="1" lower="-3.054325556" upper="3.054325556"/>		
		<axis xyz="0 1 0"/>
	</joint>  
	<joint name="neck_joint_4" type="fixed">
		<parent link="neck2"/>
		<child link="mask"/>
		<origin rpy="0.0 0.0 0.0" xyz="0 0 0"/>
	</joint> 
	<link name="table">	
	    <visual>
	      <origin rpy="0 0 0" xyz="0 0 0"/>
	      <geometry>
						<mesh filename="meshes/visual/table.stl" scale="1 1 1"/>
	      </geometry>	 
	      <material name="metal_white_grey"/>	          
	    </visual>
	    <collision>
	      <origin rpy="0 0 0" xyz="0 0 -0.26024"/>
	      <geometry>
						<box size="1 1.2 0.52048	" />
	      </geometry>	 
	      <material name="metal_white_grey"/>	              
	    </collision>	    
	    <inertial>
	      <mass value="2"/>
	      <origin rpy="0 0 0" xyz="0.0 0.0 0.0"/>
	      <inertia ixx="0.0" ixy="0.0" ixz="0.0" iyy="0.0" iyz="0.0" izz="0.0"/>
	    </inertial>	
	</link>	
	<joint name="table_joint" type="fixed">
		<parent link="body"/>
		<child link="table"/>
		<origin rpy="0.0 0.0 0.0" xyz="0 0 0"/>
	</joint> 
</robot>
